[*] Running ...
[*] Dataset loaded: D:\ProgramLanguages\Programs\Python\code-gen\reevo/problems/tsp_gls\dataset/train200_dataset.npy with 10 instances.
Traceback (most recent call last):
  File "D:\ProgramLanguages\Programs\Python\code-gen\reevo/problems/tsp_gls/eval.py", line 49, in <module>
    obj = solve(instance)
          ^^^^^^^^^^^^^^^
  File "D:\ProgramLanguages\Programs\Python\code-gen\reevo/problems/tsp_gls/eval.py", line 19, in solve
    heu = heuristics(inst.distmat.copy())
          ^^^^^^^^^^^^^^^^^^^^^^^^^^^^^^^
  File "D:\ProgramLanguages\Programs\Python\code-gen\reevo\problems\tsp_gls\gpt.py", line 16, in heuristics_v2
    heuristics_matrix[i, j] = (local_min + domain_min + distance_matrix[i, j]) / 2 + \
                        ^^^^^^^^^^^^^^^^^^^^^^^^^^^^^^^^^^^^^^^^^^^^^^^^^^^^^^^^^^^^^^^
  File "D:\Conda_data\envs\reevo\Lib\site-packages\numpy\core\fromnumeric.py", line 2953, in min
    return _wrapreduction(a, np.minimum, 'min', axis, None, out,
           ^^^^^^^^^^^^^^^^^^^^^^^^^^^^^^^^^^^^^^^^^^^^^^^^^^^^^
  File "D:\Conda_data\envs\reevo\Lib\site-packages\numpy\core\fromnumeric.py", line 88, in _wrapreduction
    return ufunc.reduce(obj, axis, dtype, out, **passkwargs)
           ^^^^^^^^^^^^^^^^^^^^^^^^^^^^^^^^^^^^^^^^^^^^^^^^^
numpy.exceptions.AxisError: axis 1 is out of bounds for array of dimension 1
