Traceback (most recent call last):
  File "E:\Projects\CO\reevo-main_1/problems/tsp_gls/eval.py", line 10, in <module>
    from gpt import heuristics_v2 as heuristics
  File "E:\Projects\CO\reevo-main_1\problems\tsp_gls\gpt.py", line 4, in <module>
    from sklearn.cluster import KMeans
ModuleNotFoundError: No module named 'sklearn'

During handling of the above exception, another exception occurred:

Traceback (most recent call last):
  File "E:\Projects\CO\reevo-main_1/problems/tsp_gls/eval.py", line 12, in <module>
    from gpt import heuristics
  File "E:\Projects\CO\reevo-main_1\problems\tsp_gls\gpt.py", line 4, in <module>
ModuleNotFoundError: No module named 'sklearn'
