[*] Running ...
[*] Dataset loaded: E:\Projects\CO\reevo-main/problems/mkp_aco\dataset/train100_dataset.npz with 5 instances.
Traceback (most recent call last):
  File "E:\Projects\CO\reevo-main/problems/mkp_aco/eval.py", line 58, in <module>
    obj = solve(prize, weight)
          ^^^^^^^^^^^^^^^^^^^^
  File "E:\Projects\CO\reevo-main/problems/mkp_aco/eval.py", line 23, in solve
    heu = heuristics(prize.copy(), weight.copy()) + 1e-9
          ^^^^^^^^^^^^^^^^^^^^^^^^^^^^^^^^^^^^^^^
  File "E:\Projects\CO\reevo-main\problems\mkp_aco\gpt.py", line 9, in heuristics_v2
    
  File "D:\Anaconda3\envs\reevo\Lib\site-packages\numpy\core\fromnumeric.py", line 2412, in any
    return _wrapreduction(a, np.logical_or, 'any', axis, None, out,
           ^^^^^^^^^^^^^^^^^^^^^^^^^^^^^^^^^^^^^^^^^^^^^^^^^^^^^^^^
  File "D:\Anaconda3\envs\reevo\Lib\site-packages\numpy\core\fromnumeric.py", line 88, in _wrapreduction
    return ufunc.reduce(obj, axis, dtype, out, **passkwargs)
           ^^^^^^^^^^^^^^^^^^^^^^^^^^^^^^^^^^^^^^^^^^^^^^^^^
numpy.exceptions.AxisError: axis 1 is out of bounds for array of dimension 1
